Workbook

Sheet Resumo Executivo
A1: Custos com Ferramentas de IA - Apresentação C-Level
A2: Consolidado mensal e projeção anual | Referência: Maio/2026
A4: Ferramenta | B4: Fornecedor / Categoria | C4: Usuários / Licenças | D4: Custo Mensal (R$) | E4: Custo Anual (R$) | F4: % do Total Mensal
A5: Builder360 R&D | B5: Contrato anual - Plataforma de IA para P&D | C5: N/A (contrato anual) | D5: =E5/12 -> 104166.67 | E5: 1250000 | F5: =D5/$D$15 -> 0.52142776
A6: Assistente Inteligente R&D | B6: Contrato anual - Plataforma de IA para P&D | C6: N/A (contrato anual) | D6: =E6/12 -> 39583.333 | E6: 475000 | F6: =D6/$D$15 -> 0.19814255
A7: Claude | B7: Anthropic - Assistente IA generalista | C7: 128 | D7: 37000 | E7: =D7*12 -> 444000 | F7: =D7/$D$15 -> 0.18521114
A8: Fortics | B8: Plataforma de atendimento IA (SZ.chat) | C8: N/A (plataforma) | D8: 7758 | E8: =D8*12 -> 93096 | F8: =D8/$D$15 -> 0.038834271
A9: GitHub Copilot | B9: GitHub - Assistente de código com IA | C9: 23 | D9: 5152 | E9: =D9*12 -> 61824 | F9: =D9/$D$15 -> 0.0257894
A10: ChatGPT | B10: OpenAI - Assistente IA generalista | C10: 10 | D10: 5100 | E10: =D10*12 -> 61200 | F10: =D10/$D$15 -> 0.025529103
A11: Adobe IA | B11: Adobe - Recursos de IA generativa (Firefly/Acrobat) | C11: 5 | D11: 640 | E11: =D11*12 -> 7680 | F11: =D11/$D$15 -> 0.0032036522
A12: Google NotebookLM | B12: Google - Pesquisa e síntese | C12: 5 | D12: 232 | E12: =D12*12 -> 2784 | F12: =D12/$D$15 -> 0.0011613239
A13: Gamma | B13: Geração de apresentações com IA | C13: 2 | D13: 140 | E13: =D13*12 -> 1680 | F13: =D13/$D$15 -> 0.00070079891
A14: Chat Copilot | B14: Microsoft - Copilot Chat (gratuito) | C14: 520 | D14: 0 | E14: =D14*12 -> 0 | F14: =D14/$D$15 -> 0
A15: TOTAL | B15: Gasto consolidado com IA | C15: =SUM(C5:C14) -> 693 | D15: =SUM(D5:D14) -> 199772 | E15: =SUM(E5:E14) -> 2397264 | F15: =SUM(F5:F14) -> 1
A18: Indicadores Chave
A19: Custo Mensal Total (R$) | E19: =D15 -> 199772
A20: Custo Anual Projetado (R$) | E20: =E15 -> 2397264
A21: Número de Ferramentas | E21: =COUNTA(A5:A14) -> 10
A22: Ferramentas Pagas | E22: =COUNTIF(D5:D14,">0") -> 9
A23: Ferramentas Gratuitas | E23: =COUNTIF(D5:D14,0) -> 1
A24: Maior gasto mensal (R$) | E24: =MAX(D5:D14) -> 104166.67
A25: Ticket médio por ferramenta paga (R$) | E25: =AVERAGEIF(D5:D14,">0") -> 22196.889
A28: Legenda: | B28: Texto azul = valores de entrada (alterar para simular cenários)
B29: Texto preto = fórmulas calculadas automaticamente
B30: Texto verde = ferramenta gratuita (custo zero)
B31: Contratos anuais (Builder360 e Assistente R&D): mensal calculado como anual/12
A38: Usuários com mais de uma ferramenta de IA (exclui Chat Copilot)
A39: Total: 16 usuários | Custo mensal individual e consolidado por ferramentas combinadas
A41: # | B41: Nome | C41: Área | D41: Cargo | E41: Ferramentas utilizadas (com tier Claude) | F41: Qtd | G41: Custo Mensal | H41: Custo Anual
A42: 1 | B42: Rodrigo da Rosa Walter | C42: CC | D42: Especialista em Inovação e Atendimento Digital | E42: Adobe IA + ChatGPT + Claude (Standard) + NotebookLM | F42: 4 | G42: 824.4 | H42: 9892.8
A43: 2 | B43: Rodrigo Franco Nunes | C43: CC | D43: Especialista em Inovação e Atendimento Digital | E43: Adobe IA + ChatGPT + Claude (Standard) + NotebookLM | F43: 4 | G43: 824.4 | H43: 9892.8
A44: 3 | B44: Luis Fernando Garuti | C44: CC | D44: Especialista em Inovação e Atendimento Digital | E44: Adobe IA + ChatGPT + Claude (Standard) + NotebookLM | F44: 4 | G44: 824.4 | H44: 9892.8
A45: 4 | B45: Manuela Bolsonaro Ferreira Lima Miziara | C45: CC | D45: Coordenador(a) em Sucesso do Cliente | E45: ChatGPT + Claude (Standard) + Gamma + NotebookLM | F45: 4 | G45: 766.4 | H45: 9196.8
A46: 5 | B46: Luiz Augusto Ribeiro Ferro | C46: CC | D46: Especialista em Inovação e Atendimento Digital | E46: Adobe IA + ChatGPT + Claude (Standard) | F46: 3 | G46: 778 | H46: 9336
A47: 6 | B47: Rodolfo Americo Rodrigues Martins | C47: CC | D47: Especialista em Inovação e Atendimento Digital | E47: Adobe IA + ChatGPT + Claude (Standard) | F47: 3 | G47: 778 | H47: 9336
A48: 7 | B48: Livia Piovesan e Sa Zepponi | C48: CC | D48: Vice-Presidente | E48: ChatGPT + Claude (Standard) + Gamma | F48: 3 | G48: 720 | H48: 8640
A49: 8 | B49: Gean Marcelo Vailatti | C49: R&D | D49: Arquiteto(a) de Software | E49: Claude (Premium) + GitHub Copilot | F49: 2 | G49: 894 | H49: 10728
A50: 9 | B50: Edison Henrique Andreassy | C50: R&D | D50: Arquiteto(a) de Software | E50: Claude (Premium) + GitHub Copilot | F50: 2 | G50: 894 | H50: 10728
A51: 10 | B51: Joao Guilherme Rossanesi Matos | C51: R&D | D51: Analista DEVOPS Pl | E51: Claude (Premium) + GitHub Copilot | F51: 2 | G51: 894 | H51: 10728
A52: 11 | B52: Andre Carlos Dias Silva | C52: CC | D52: Especialista em Inovação e Atendimento Digital | E52: ChatGPT + Claude (Standard) | F52: 2 | G52: 650 | H52: 7800
...

Sheet IA Operacional (sem produt R&D)
A1: IA Operacional - Excluindo Contratos R&D
A2: Visão sem Builder360 R&D e Assistente Inteligente R&D | Referência: Maio/2026
A4: Ferramenta | B4: Fornecedor / Categoria | C4: Usuários / Licenças | D4: Custo Mensal (R$) | E4: Custo Anual (R$) | F4: % do Total Mensal
A5: Claude | B5: Anthropic - Assistente IA generalista | C5: 128 | D5: 37000 | E5: =D5*12 -> 444000 | F5: =D5/$D$13 -> 0.66045482
A6: Fortics | B6: Plataforma de atendimento IA (SZ.chat) | C6: N/A (plataforma) | D6: 7758 | E6: =D6*12 -> 93096 | F6: =D6/$D$13 -> 0.13848131
A7: GitHub Copilot | B7: GitHub - Assistente de código com IA | C7: 23 | D7: 5152 | E7: =D7*12 -> 61824 | F7: =D7/$D$13 -> 0.091963871
A8: ChatGPT | B8: OpenAI - Assistente IA generalista | C8: 10 | D8: 5100 | E8: =D8*12 -> 61200 | F8: =D8/$D$13 -> 0.091035665
A9: Adobe IA | B9: Adobe - Recursos de IA generativa (Firefly/Acrobat) | C9: 5 | D9: 640 | E9: =D9*12 -> 7680 | F9: =D9/$D$13 -> 0.011424083
A10: Google NotebookLM | B10: Google - Pesquisa e síntese | C10: 5 | D10: 232 | E10: =D10*12 -> 2784 | F10: =D10/$D$13 -> 0.0041412302
A11: Gamma | B11: Geração de apresentações com IA | C11: 2 | D11: 140 | E11: =D11*12 -> 1680 | F11: =D11/$D$13 -> 0.0024990182
A12: Chat Copilot | B12: Microsoft - Copilot Chat (gratuito) | C12: 520 | D12: 0 | E12: =D12*12 -> 0 | F12: =D12/$D$13 -> 0
A13: TOTAL | B13: Gasto consolidado de IA operacional | C13: =SUM(C5:C12) -> 693 | D13: =SUM(D5:D12) -> 56022 | E13: =SUM(E5:E12) -> 672264 | F13: =SUM(F5:F12) -> 1
A16: Comparativo: Com R&D x Sem R&D
A17: Total Mensal (sem R&D) | E17: =D13 -> 56022
A18: Total Anual (sem R&D) | E18: =E13 -> 672264
A19: Total Mensal (com R&D - Aba Resumo Executivo) | E19: ='Resumo Executivo'!D15 -> 199772
A20: Total Anual (com R&D - Aba Resumo Executivo) | E20: ='Resumo Executivo'!E15 -> 2397264
A21: Contratos R&D Mensal | E21: ='Resumo Executivo'!D15-D13 -> 143750
A22: Contratos R&D Anual | E22: ='Resumo Executivo'!E15-E13 -> 1725000
A23: % R&D no total | E23: =('Resumo Executivo'!D15-D13)/'Resumo Executivo'!D15 -> 0.71957031
A26: Legenda: | B26: Texto azul = valores de entrada (alterar para simular cenários)
B27: Texto preto = fórmulas calculadas automaticamente
B28: Texto verde = ferramenta gratuita / referência cruzada com outra aba
B29: Aba útil para discutir o gasto de IA excluindo contratos estratégicos de P&D

Sheet Custo por Área
A1: Custos de IA por Área
A2: Distribuição do investimento por área da empresa | Fortics → CC | Contratos R&D → R&D
A4: Resumo Consolidado por Área
A5: Área | B5: Descrição | C5: Usuários únicos | D5: Custo Mensal | E5: Custo Anual | F5: % do Total
A6: R&D | B6: Research & Development | C6: 51 | D6: 166520 | E6: 1998240 | F6: =D6/$D$11 -> 0.83587831
A7: CC | B7: Customer Care | C7: 17 | D7: 15553.6 | E7: 186643.2 | F7: =D7/$D$11 -> 0.078074207
A8: G&A | B8: General & Administrative | C8: 48 | D8: 13222 | E8: 158664 | F8: =D8/$D$11 -> 0.066370304
A9: PS | B9: Professional Services | C9: 20 | D9: 2800 | E9: 33600 | F9: =D9/$D$11 -> 0.014055124
A10: S&M | B10: Sales & Marketing | C10: 8 | D10: 1120 | E10: 13440 | F10: =D10/$D$11 -> 0.0056220497
A11: TOTAL | B11: Gasto consolidado por área | C11: 144 | D11: =SUM(D6:D10) -> 199215.6 | E11: =SUM(E6:E10) -> 2390587.2 | F11: =SUM(F6:F10) -> 1
A12: Observação: O total acima reflete apenas licenças alocadas a usuários identificados (R$ 199.215,60/mês). O total contratado no Resumo Executivo é R$ 199.772,00/mês — diferença de R$ 556,40 corresponde a 1 licença ChatGPT ociosa (R$ 510) e 1 licença NotebookLM ociosa (R$ 46,40).
A14: Detalhamento por Área — Composição do Gasto
A16: R&D • Research & Development • Mensal: R$ 166.520,00 • Anual: R$ 1.998.240,00
A17: Ferramenta | B17: Usuários | C17: Custo Mensal | D17: Custo Anual | E17: % da Área | F17: Observação
A18: Builder360 R&D | B18: — | C18: 104166.67 | D18: 1250000 | E18: 0.62555048 | F18: Contrato / plataforma (sem licenciamento por usuário)
A19: Assistente Inteligente R&D | B19: — | C19: 39583.333 | D19: 475000 | E19: 0.23770918 | F19: Contrato / plataforma (sem licenciamento por usuário)
A20: Claude | B20: 36 | C20: 18290 | D20: 219480 | E20: 0.10983666 | F20: Premium: 25 | Standard: 11
A21: GitHub Copilot | B21: 20 | C21: 4480 | D21: 53760 | E21: 0.026903675
A23: CC • Customer Care • Mensal: R$ 15.553,60 • Anual: R$ 186.643,20
A24: Ferramenta | B24: Usuários | C24: Custo Mensal | D24: Custo Anual | E24: % da Área | F24: Observação
A25: Fortics | B25: — | C25: 7758 | D25: 93096 | E25: 0.49879128 | F25: Contrato / plataforma (sem licenciamento por usuário)
A26: ChatGPT | B26: 9 | C26: 4590 | D26: 55080 | E26: 0.29510853
A27: Claude | B27: 16 | C27: 2240 | D27: 26880 | E27: 0.14401811 | F27: Premium: 0 | Standard: 16
A28: Adobe IA | B28: 5 | C28: 640 | D28: 7680 | E28: 0.04114803
A29: NotebookLM | B29: 4 | C29: 185.6 | D29: 2227.2 | E29: 0.011932929
A30: Gamma | B30: 2 | C30: 140 | D30: 1680 | E30: 0.0090011316
A32: G&A • General & Administrative • Mensal: R$ 13.222,00 • Anual: R$ 158.664,00
A33: Ferramenta | B33: Usuários | C33: Custo Mensal | D33: Custo Anual | E33: % da Área | F33: Observação
A34: Claude | B34: 48 | C34: 12550 | D34: 150600 | E34: 0.94917562 | F34: Premium: 11 | Standard: 37
A35: GitHub Copilot | B35: 3 | C35: 672 | D35: 8064 | E35: 0.050824384
A37: PS • Professional Services • Mensal: R$ 2.800,00 • Anual: R$ 33.600,00
A38: Ferramenta | B38: Usuários | C38: Custo Mensal | D38: Custo Anual | E38: % da Área | F38: Observação
A39: Claude | B39: 20 | C39: 2800 | D39: 33600 | E39: 1 | F39: Premium: 0 | Standard: 20
A41: S&M • Sales & Marketing • Mensal: R$ 1.120,00 • Anual: R$ 13.440,00
A42: Ferramenta | B42: Usuários | C42: Custo Mensal | D42: Custo Anual | E42: % da Área | F42: Observação
A43: Claude | B43: 8 | C43: 1120 | D43: 13440 | E43: 1 | F43: Premium: 0 | Standard: 8

Sheet Custo por Área 2
A1: Custos de IA por Área — Sem Contratos R&D
A2: Visão excluindo Builder360 R&D e Assistente Inteligente R&D | Fortics → CC
A4: Resumo Consolidado por Área (IA Operacional)
A5: Área | B5: Descrição | C5: Usuários únicos | D5: Custo Mensal | E5: Custo Anual | F5: % do Total
A6: R&D | B6: Research & Development | C6: 51 | D6: 22770 | E6: 273240 | F6: =D6/$D$11 -> 0.41052472
A7: CC | B7: Customer Care | C7: 17 | D7: 15553.6 | E7: 186643.2 | F7: =D7/$D$11 -> 0.28041885
A8: G&A | B8: General & Administrative | C8: 48 | D8: 13222 | E8: 158664 | F8: =D8/$D$11 -> 0.23838199
A9: PS | B9: Professional Services | C9: 20 | D9: 2800 | E9: 33600 | F9: =D9/$D$11 -> 0.05048174
A10: S&M | B10: Sales & Marketing | C10: 8 | D10: 1120 | E10: 13440 | F10: =D10/$D$11 -> 0.020192696
A11: TOTAL | B11: IA operacional (sem contratos R&D) | C11: 144 | D11: =SUM(D6:D10) -> 55465.6 | E11: =SUM(E6:E10) -> 665587.2 | F11: =SUM(F6:F10) -> 1
A14: Comparativo: Com R&D × Sem R&D
A15: Total Mensal (sem R&D - aqui) | E15: =D11 -> 55465.6
A16: Total Anual (sem R&D - aqui) | E16: =E11 -> 665587.2
A17: Total Mensal (com R&D - aba Custo por Área) | E17: ='Custo por Área'!D11 -> 199215.6
A18: Total Anual (com R&D - aba Custo por Área) | E18: ='Custo por Área'!E11 -> 2390587.2
A19: Diferença mensal (= contratos R&D) | E19: ='Custo por Área'!D11-D11 -> 143750
A20: % economia se cancelados os contratos R&D | E20: =('Custo por Área'!D11-D11)/'Custo por Área'!D11 -> 0.72158004
A23: Detalhamento por Área — Composição do Gasto (sem contratos R&D)
A25: R&D • Research & Development • Mensal: R$ 22.770,00 • Anual: R$ 273.240,00
A26: Ferramenta | B26: Usuários | C26: Custo Mensal | D26: Custo Anual | E26: % da Área | F26: Observação
A27: Claude | B27: 36 | C27: 18290 | D27: 219480 | E27: 0.80324989 | F27: Premium: 25 | Standard: 11
A28: GitHub Copilot | B28: 20 | C28: 4480 | D28: 53760 | E28: 0.19675011
A30: CC • Customer Care • Mensal: R$ 15.553,60 • Anual: R$ 186.643,20
A31: Ferramenta | B31: Usuários | C31: Custo Mensal | D31: Custo Anual | E31: % da Área | F31: Observação
A32: Fortics | B32: — | C32: 7758 | D32: 93096 | E32: 0.49879128 | F32: Plataforma de atendimento (sem licenciamento por usuário)
A33: ChatGPT | B33: 9 | C33: 4590 | D33: 55080 | E33: 0.29510853
A34: Claude | B34: 16 | C34: 2240 | D34: 26880 | E34: 0.14401811 | F34: Premium: 0 | Standard: 16
A35: Adobe IA | B35: 5 | C35: 640 | D35: 7680 | E35: 0.04114803
A36: NotebookLM | B36: 4 | C36: 185.6 | D36: 2227.2 | E36: 0.011932929
A37: Gamma | B37: 2 | C37: 140 | D37: 1680 | E37: 0.0090011316
A39: G&A • General & Administrative • Mensal: R$ 13.222,00 • Anual: R$ 158.664,00
A40: Ferramenta | B40: Usuários | C40: Custo Mensal | D40: Custo Anual | E40: % da Área | F40: Observação
A41: Claude | B41: 48 | C41: 12550 | D41: 150600 | E41: 0.94917562 | F41: Premium: 11 | Standard: 37
A42: GitHub Copilot | B42: 3 | C42: 672 | D42: 8064 | E42: 0.050824384
A44: PS • Professional Services • Mensal: R$ 2.800,00 • Anual: R$ 33.600,00
A45: Ferramenta | B45: Usuários | C45: Custo Mensal | D45: Custo Anual | E45: % da Área | F45: Observação
A46: Claude | B46: 20 | C46: 2800 | D46: 33600 | E46: 1 | F46: Premium: 0 | Standard: 20
A48: S&M • Sales & Marketing • Mensal: R$ 1.120,00 • Anual: R$ 13.440,00
A49: Ferramenta | B49: Usuários | C49: Custo Mensal | D49: Custo Anual | E49: % da Área | F49: Observação
A50: Claude | B50: 8 | C50: 1120 | D50: 13440 | E50: 1 | F50: Premium: 0 | Standard: 8

Sheet Usuários por Ferramenta
A1: Usuários por Ferramenta de IA
A2: Listagem nominal por licença | Custo por usuário (Claude: Standard R$ 140 / Premium R$ 670) | Dados QL 05/2026
A4: Claude (128 listados / 128 licenças) • Standard: R$ 140,00 | Premium: R$ 670,00
A5: # | B5: Nome | C5: E-mail | D5: Cargo / Função | E5: Área | F5: Gestor Imediato | G5: Tier / Plano | H5: Custo Mensal/Usuário
A6: 1 | B6: Alcenir Vergilio Negri | C6: alcenir.negri@governancabrasil.com.br | D6: Analista de Negocios Pl | E6: R&D | F6: Jader Elias Franz | G6: Premium | H6: 670
A7: 2 | B7: Alessandro Cesar Torido | C7: alessandro.torido@governancabrasil.com.br | D7: Gerente de Operacoes de TI | E7: G&A | F7: Rafael Goncalves Denardi | G7: Premium | H7: 670
A8: 3 | B8: Andre Vieira da Costa | C8: andre.costa@governancabrasil.com.br | D8: Analista de Negocios Pl | E8: R&D | F8: Jader Elias Franz | G8: Premium | H8: 670
A9: 4 | B9: Christian Rita de Moura | C9: christian.moura@governancabrasil.com.br | D9: Gerente de Gente e Cultura | E9: G&A | F9: Marcelo Ferreira Chaves de Oliveira Lima | G9: Premium | H9: 670
A10: 5 | B10: Cleber Nardelli | C10: cleber.nardelli@governancabrasil.com.br | D10: Gerente de Tecnologia e Pesquisa | E10: R&D | F10: Ivan Correia Filagrana | G10: Premium | H10: 670
A11: 6 | B11: Davi Marin Rodrigues Silva | C11: davi.silva@governancabrasil.com.br | D11: Arquiteto(a) de Software | E11: R&D | F11: Cleber Nardelli | G11: Premium | H11: 670
A12: 7 | B12: Debora Cristina Leira Ramos | C12: debora.ramos@governancabrasil.com.br | D12: Gerente de Desenvolvimento | E12: R&D | F12: Saulo Reschke Parizotto | G12: Premium | H12: 670
A13: 8 | B13: Denis Augusto Vicentainer | C13: denis.vicentainer@governancabrasil.com.br | D13: Engenheiro(a) de Inteligência Artificial (IA) | E13: R&D | F13: Joao Vitor Miguel | G13: Premium | H13: 670
A14: 9 | B14: Djeferson Preis | C14: djeferson.preis@governancabrasil.com.br | D14: Desenvolvedor(a) Sr | E14: R&D | F14: Joao Vitor Miguel | G14: Premium | H14: 670
A15: 10 | B15: Edison Henrique Andreassy | C15: henrique.andreassy@governancabrasil.com.br | D15: Arquiteto(a) de Software | E15: R&D | F15: Cleber Nardelli | G15: Premium | H15: 670
A16: 11 | B16: Flavio Luiz Junior da Silva | C16: flavio.silva@governancabrasil.com.br | D16: Gerente de Desenvolvimento | E16: R&D | F16: Saulo Reschke Parizotto | G16: Premium | H16: 670
A17: 12 | B17: Frederico Marques Lourente | C17: frederico.lourente@governancabrasil.com.br | D17: Gerente de Produto | E17: R&D | F17: Ivan Correia Filagrana | G17: Premium | H17: 670
... A133: 128 | B133: Yasmine Lima de Oliveira | C133: yasmine.oliveira@governancabrasil.com.br | D133: Analista Adm Despesas Jr | E133: G&A | F133: Vanessa Bittencourt Bandeira dos Reis | G133: Standard | H133: 140
A134: Distribuição Claude por Área: G&A: 48 | R&D: 36 | PS: 20 | CC: 16 | S&M: 8
A135: Resumo Claude: Premium 36 × R$ 670 = R$ 24.120.00 | Standard 92 × R$ 140 = R$ 12.880.00 | TOTAL: R$ 37.000.00/mês
A137: GitHub Copilot (23 listados / 23 licenças) • R$ 224.00/usuário/mês
A138: # | B138: Nome | C138: E-mail | D138: Cargo / Função | E138: Área | F138: Gestor Imediato | G138: Tier / Plano | H138: Custo Mensal/Usuário
A139: 1 | B139: Edison Henrique Andreassy | C139: henrique.andreassy@governancabrasil.com.br | D139: Arquiteto(a) de Software | E139: R&D | F139: Cleber Nardelli | H139: 224
A140: 2 | B140: Bruno Oliveira Lucindo | C140: bruno.lucindo@governancabrasil.com.br | D140: Analista de Sistemas Sr | E140: R&D | F140: Gabriel Theiss | H140: 224
A141: 3 | B141: Washington Borges Rosa | C141: washington.rosa@governancabrasil.com.br | D141: Desenvolvedor(a) Sr | E141: G&A | F141: Alessandro Cesar Torido | H141: 224
A142: 4 | B142: Alex Fernandes Gregio | C142: alex.gregio@governancabrasil.com.br | D142: Analista de Sistemas Sr | E142: R&D | F142: Leirson Helio Schiestl | H142: 224
A143: 5 | B143: Jean Marcello Matias do Amaral | C143: jean.amaral@governancabrasil.com.br | D143: Analista de Testes Pl | E143: R&D | F143: Gabriel Theiss | H143: 224
A144: 6 | B144: Marcelino Rogerio Barbosa Junior | C144: marcelino.junior@governancabrasil.com.br | D144: Analista de Sistemas Sr | E144: R&D | F144: Leirson Helio Schiestl | H144: 224
A145: 7 | B145: Fernando Dias Rozas | C145: fernando.rozas@governancabrasil.com.br | D145: Analista de Sistemas Sr | E145: R&D | F145: Flavio Luiz Junior da Silva | H145: 224
A146: 8 | B146: Gean Marcelo Vailatti | C146: gean.vailatti@governancabrasil.com.br | D146: Arquiteto(a) de Software | E146: R&D | F146: Sulema Munoz Montesino Andreassy | H146: 224
A147: 9 | B147: Paulo Ricardo de Oliveira Freitas Rodrigues | C147: paulo.rodrigues@governancabrasil.com.br | D147: Desenvolvedor(a) Jr | E147: G&A | F147: Alessandro Cesar Torido | H147: 224
A148: 10 | B148: Henrique Bespalhuk Facci | C148: henrique.facci@governancabrasil.com.br | D148: Analista de Sistemas Sr | E148: R&D | F148: Gabriel Theiss | H148: 224
A149: 11 | B149: Joao Guilherme Rossanesi Matos | C149: joao.matos@governancabrasil.com.br | D149: Analista DEVOPS Pl | E149: R&D | F149: Cleber Nardelli | H149: 224
A150: 12 | B150: Felipe Raphael Mareco Lamarao | C150: felipe.lamarao@governancabrasil.com.br | D150: Analista de Testes Pl | E150: R&D | F150: Debora Cristina Leira Ramos | H150: 224
... A161: 23 | B161: Ricardo Cordeiro Silva | C161: ricardo.silva@governancabrasil.com.br | D161: Analista de Testes Pl | E161: R&D | F161: Debora Cristina Leira Ramos | H161: 224
A162: Distribuição GitHub Copilot por Área: R&D: 20 | G&A: 3
A164: ChatGPT (9 listados / 10 licenças) • R$ 510.00/usuário/mês
A165: # | B165: Nome | C165: E-mail | D165: Cargo / Função | E165: Área | F165: Gestor Imediato | G165: Tier / Plano | H165: Custo Mensal/Usuário
A166: 1 | B166: Luis Fernando Garuti | C166: luiz.garuti@governancabrasil.com.br | D166: Especialista em Inovação e Atendimento Digital | E166: CC | F166: Manuela Bolsonaro Ferreira Lima Miziara | H166: 510
A167: 2 | B167: Andrews Fernando da Silva | C167: andrews.silva@governancabrasil.com.br | D167: Consultor(a) de Produto Pl | E167: PS | F167: Sheila Cristina Basotti | H167: 510
A168: 3 | B168: Livia Piovesan e Sa Zepponi | C168: livia.sa@governancabrasil.com.br | D168: Vice-Presidente | E168: CC | F168: Tiago Padilha Serpa | H168: 510
...

Sheet Detalhamento por Ferramenta
A1: Detalhamento por Ferramenta - Custo por Usuário
A3: Ferramenta | B3: Usuários | C3: Custo Mensal (R$) | D3: Custo / Usuário / Mês (R$) | E3: Custo / Usuário / Ano (R$)
A4: Claude | B4: 128 | C4: 37000 | D4: =C4/B4 -> 289.0625 | E4: =D4*12 -> 3468.75
A5: ChatGPT | B5: 10 | C5: 5100 | D5: =C5/B5 -> 510 | E5: =D5*12 -> 6120
A6: GitHub Copilot | B6: 23 | C6: 5152 | D6: =C6/B6 -> 224 | E6: =D6*12 -> 2688
A7: Adobe IA | B7: 5 | C7: 640 | D7: =C7/B7 -> 128 | E7: =D7*12 -> 1536
A8: Google NotebookLM | B8: 5 | C8: 232 | D8: =C8/B8 -> 46.4 | E8: =D8*12 -> 556.8
A9: Gamma | B9: 2 | C9: 140 | D9: =C9/B9 -> 70 | E9: =D9*12 -> 840
A10: Builder360 R&D | B10: N/A | C10: 104166.67 | D10: Contrato anual de R$ 1.250.000 (mensal = anual/12)
A11: Assistente Inteligente R&D | B11: N/A | C11: 39583.333 | D11: Contrato anual de R$ 475.000 (mensal = anual/12)
A12: Fortics | B12: N/A | C12: 7758 | D12: Plataforma (sem licenciamento por usuário)
A13: Chat Copilot | B13: 520 | C13: 0 | D13: Disponível sem custo para a empresa
A16: Observações
A17: • Os valores de entrada (azul) podem ser editados — as fórmulas se recalculam automaticamente.
A18: • O custo médio por usuário difere significativamente entre ferramentas — útil para decisões de consolidação de licenças.
A19: • Fortics é cobrado como plataforma (não há licenciamento por usuário individual).
A20: • Builder360 R&D é contrato anual fechado em R$ 1.250.000 — equivalente mensal de R$ 104.166,67.
A21: • Assistente Inteligente R&D é contrato anual fechado em R$ 475.000 — equivalente mensal de R$ 39.583,33.
A22: • Chat Copilot (Microsoft) está disponível sem custo adicional — oportunidade de adoção ampla sem impacto financeiro.
A23: • Projeção anual = custo mensal × 12 (não considera reajustes contratuais).
